<?xml version="1.0"?>
<robot name="Castor Wheel Robot">
    <!-- Material Blue -->
    <material name="blue">
        <color rgba="0 0 1 1"/>
    </material>
    <!-- Material Red -->
    <material name="red">
        <color rgba="1 0 0 1"/>
    </material>
    <!-- Material Green -->
    <material name="green">
        <color rgba="0 1 0 1"/>
    </material>
    <!-- Empty footprint link -->
    <link name="base_footprint">
    </link>
    <!-- Robot base link -->
    <link name="base_link">
        <visual>
            <geometry>
                <box size="0.6 0.4 0.2"/>
            </geometry>
            <material name="blue"/>
            <origin xyz="0 0 0.1" rpy="0 0 0"/>
        </visual>
    </link>
    <!-- Joint between base_footprint and base -->
    <joint name="base_footprint_base_link_joint" type="fixed">
        <parent link="base_footprint"/>
        <child link="base_link"/>
        <origin xyz="0 0 0.1" rpy="0 0 0"/>
    </joint>
    <!-- Left Wheel Link -->
    <link name="left_wheel">
        <visual>
            <geometry>
                <cylinder radius="0.1" length="0.05"/>
            </geometry>
            <material name="green"/>
            <origin xyz="0 0 0" rpy="0 0 0"/>
        </visual>
    </link>
    <!-- Joint between base and left wheel -->
    <joint name="base_link_left_wheel_joint" type="continuous">
        <parent link="base_link"/>
        <child link="left_wheel"/>
        <origin xyz="-0.15 0.225 0" rpy="1.57 0 0"/>
        <axis xyz="0 0 1"/>
    </joint>
    <!-- Right Wheel Link -->
    <link name="right_wheel">
        <visual>
            <geometry>
                <cylinder radius="0.1" length="0.05"/>
            </geometry>
            <material name="green"/>
            <origin xyz="0 0 0" rpy="0 0 0"/>
        </visual>
    </link>
    <!-- Joint between base and right wheel -->
    <joint name="base_link_right_wheel_joint" type="continuous">
        <parent link="base_link"/>
        <child link="right_wheel"/>
        <origin xyz="-0.15 -0.225 0" rpy="1.57 0 0"/>
        <axis xyz="0 0 1"/>
    </joint>
    <!-- Castor Wheel Link -->
    <link name="castor_wheel">
        <visual>
            <geometry>
                <sphere radius="0.05"/>
            </geometry>
            <material name="green"/>
            <origin xyz="0 0 0" rpy="0 0 0"/>
        </visual>
    </link>
    <!-- Joint between base and castor wheel -->
    <joint name="base_link_castor_wheel_joint" type="fixed">
        <parent link="base_link"/>
        <child link="castor_wheel"/>
        <origin xyz="0.2 0 -0.05" rpy="0 0 0"/>
    </joint>
</robot>